<?xml version="1.0"?>
<robot xmlns:xacro="http://www.ros.org/wiki/xacro">
    <xacro:macro name="insert_robot" params="prefix model parent *origin">
        <link name="${prefix}base_link">
            <visual>
                <origin xyz="0 0 0" rpy="0 0 0"/>
                <geometry>
                    <mesh filename="package://elite_robot_description/meshes/${model}/visual/base.dae" scale="1 1 1"/>
                </geometry>
            </visual>
            <collision>
                <origin xyz="0 0 0" rpy="0 0 0"/>
                <geometry>
                    <mesh filename="package://elite_robot_description/meshes/${model}/collison/base.stl" scale="1 1 1"/>
                </geometry>
            </collision>
            <inertial>
                <origin xyz="0 0 0" rpy="0 0 0.042"/>
                <mass value="1.753476"/>
                <inertia ixx="0.003313" ixy="0" ixz="0" iyy="0.003312" iyz="0" izz="0.004254"/>
            </inertial>
        </link>

        <joint name="base_link_fixed_joint" type="fixed">
            <parent link="${parent}"/>
            <child link="${prefix}base_link"/>
            <xacro:insert_block name="origin" />
        </joint>

        <link name="${prefix}link1">
            <visual>
                <origin xyz="0 0 0" rpy="0 0 0"/>
                <geometry>
                    <mesh filename="package://elite_robot_description/meshes/${model}/visual/link1.dae" scale="1 1 1"/>
                </geometry>
            </visual>
            <collision>
                <origin xyz="0 0 0" rpy="0 0 0"/>
                <geometry>
                    <mesh filename="package://elite_robot_description/meshes/${model}/collison/link1.stl" scale="1 1 1"/>
                </geometry>
            </collision>
            <inertial>
                <origin xyz="0 -0.009 0.072" rpy="0 0 0"/>
                <mass value="2.431303"/>
                <inertia ixx="0.006723" ixy="0" ixz="0.000001" iyy="0.006327" iyz="0.000046" izz="0.005198"/>
            </inertial>
        </link>

        <joint name="${prefix}joint1" type="revolute">
            <parent link="${prefix}base_link"/>
            <child link="${prefix}link1"/>
            <origin xyz="0 0 0.0919" rpy="0 0 0"/>
            <axis xyz="0 0 1"/>
            <limit effort="1000" velocity="1.0" lower="${-pi}" upper="${pi}"/>
            <safety_controller k_position="100.0" k_velocity="40.0" soft_lower_limit="${-pi}" soft_upper_limit="${pi}" />
        </joint>

        <link name="${prefix}link2">
            <visual>
                <origin xyz="0 0 0" rpy="0 0 0"/>
                <geometry>
                    <mesh filename="package://elite_robot_description/meshes/${model}/visual/link2.dae" scale="1 1 1"/>
                </geometry>
            </visual>
            <collision>
                <origin xyz="0 0 0" rpy="0 0 0"/>
                <geometry>
                    <mesh filename="package://elite_robot_description/meshes/${model}/collison/link2.stl" scale="1 1 1"/>
                </geometry>
            </collision>
            <inertial>
                <origin xyz="0.199 0.073 0.000" rpy="0 0 0"/>
                <mass value="10.308232"/>
                <inertia ixx="0.027417" ixy="-0.000970" ixz="0.000007" iyy="0.233058" iyz="0" izz="0.240741"/>
            </inertial>
        </link>

        <joint name="${prefix}joint2" type="revolute">
            <parent link="${prefix}link1"/>
            <child link="${prefix}link2"/>
            <origin xyz="0 -0.0704 0.0706" rpy="0 0 ${pi}"/>
            <axis xyz="0 1 0"/>
            <limit effort="1000" velocity="1.0" lower="${-pi}" upper="${pi}"/>
            <safety_controller k_position="100.0" k_velocity="40.0" soft_lower_limit="${-pi}" soft_upper_limit="${pi}" />
        </joint>

        <link name="${prefix}link3">
            <visual>
                <origin xyz="0 0 0" rpy="0 0 0"/>
                <geometry>
                    <mesh filename="package://elite_robot_description/meshes/${model}/visual/link3.dae" scale="1 1 1"/>
                </geometry>
            </visual>
            <collision>
                <origin xyz="0 0 0" rpy="0 0 0"/>
                <geometry>
                    <mesh filename="package://elite_robot_description/meshes/${model}/collison/link3.stl" scale="1 1 1"/>
                </geometry>
            </collision>
            <inertial>
                <origin xyz="0.194 -0.058 0.000" rpy="0 0 0"/>
                <mass value="5.342591"/>
                <inertia ixx="0.008507" ixy="0.005298" ixz="0.000001" iyy="0.092157" iyz="0" izz="0.094359"/>
            </inertial>
        </link>

        <joint name="${prefix}joint3" type="revolute">
            <parent link="${prefix}link2"/>
            <child link="${prefix}link3"/>
            <origin xyz="0.427 0.0034 0" rpy="0 0 0"/>
            <axis xyz="0 1 0"/>
            <limit effort="1000" velocity="1.0" lower="${-pi}" upper="${pi}"/>
            <safety_controller k_position="100.0" k_velocity="40.0" soft_lower_limit="${-pi}" soft_upper_limit="${pi}" />
        </joint>

        <link name="${prefix}link4">
            <visual>
                <origin xyz="0 0 0" rpy="0 0 0"/>
                <geometry>
                    <mesh filename="package://elite_robot_description/meshes/${model}/visual/link4.dae" scale="1 1 1"/>
                </geometry>
            </visual>
            <collision>
                <origin xyz="0 0 0" rpy="0 0 0"/>
                <geometry>
                    <mesh filename="package://elite_robot_description/meshes/${model}/collison/link4.stl" scale="1 1 1"/>
                </geometry>
            </collision>
            <inertial>
                <origin xyz="0 0.064 0.006" rpy="0 0 0"/>
                <mass value="1.119554"/>
                <inertia ixx="0.002172" ixy="0" ixz="0" iyy="0.001469" iyz="-0.000062" izz="0.001640"/>
            </inertial>
        </link>

        <joint name="${prefix}joint4" type="revolute">
            <parent link="${prefix}link3"/>
            <child link="${prefix}link4"/>
            <origin xyz="0.3905 -0.0118 0" rpy="0 0 0"/>
            <axis xyz="0 1 0"/>
            <limit effort="1000" velocity="1.0" lower="${-pi}" upper="${pi}"/>
            <safety_controller k_position="100.0" k_velocity="40.0" soft_lower_limit="${-pi}" soft_upper_limit="${pi}" />
        </joint>

        <link name="${prefix}link5">
            <visual>
                <origin xyz="0 0 0" rpy="0 0 0"/>
                <geometry>
                    <mesh filename="package://elite_robot_description/meshes/${model}/visual/link5.dae" scale="1 1 1"/>
                </geometry>
            </visual>
            <collision>
                <origin xyz="0 0 0" rpy="0 0 0"/>
                <geometry>
                    <mesh filename="package://elite_robot_description/meshes/${model}/collison/link5.stl" scale="1 1 1"/>
                </geometry>
            </collision>
            <inertial>
                <origin xyz="0 -0.006 0.042" rpy="0 0 0"/>
                <mass value="0.801370"/>
                <inertia ixx="0.001175" ixy="0" ixz="0" iyy="0.000723" iyz="0.000009" izz="0.001108"/>
            </inertial>
        </link>

        <joint name="${prefix}joint5" type="revolute">
            <parent link="${prefix}link4"/>
            <child link="${prefix}link5"/>
            <origin xyz="0 0.0855 -0.049" rpy="0 ${pi} 0"/>
            <axis xyz="0 0 1"/>
            <limit effort="1000" velocity="1.0" lower="${-pi}" upper="${pi}"/>
            <safety_controller k_position="100.0" k_velocity="40.0" soft_lower_limit="${-pi}" soft_upper_limit="${pi}" />
        </joint>

        <link name="${prefix}link6">
            <visual>
                <origin xyz="0 0 0" rpy="0 0 0"/>
                <geometry>
                    <mesh filename="package://elite_robot_description/meshes/${model}/visual/link6.dae" scale="1 1 1"/>
                </geometry>
            </visual>
            <collision>
                <origin xyz="0 0 0" rpy="0 0 0"/>
                <geometry>
                    <mesh filename="package://elite_robot_description/meshes/${model}/collison/link6.stl" scale="1 1 1"/>
                </geometry>
            </collision>
            <inertial>
                <origin xyz="0 0.021 0.001" rpy="0 0 0"/>
                <mass value="0.243472"/>
                <inertia ixx="0.000124" ixy="0" ixz="0" iyy="0.000173" iyz="0" izz="0.000119"/>
            </inertial>
        </link>

        <joint name="${prefix}joint6" type="revolute">
            <parent link="${prefix}link5"/>
            <child link="${prefix}link6"/>
            <origin xyz="0 0.049 0.0475" rpy="0 0 0"/>
            <axis xyz="0 1 0"/>
            <limit effort="1000" velocity="1.0" lower="${-pi}" upper="${pi}"/>
            <safety_controller k_position="100.0" k_velocity="40.0" soft_lower_limit="${-pi}" soft_upper_limit="${pi}" />
        </joint>

        <link name="${prefix}tool"/>

        <joint name="${prefix}tool_fixed_joint" type="fixed">
            <parent link="${prefix}link6"/>
            <child link="${prefix}tool"/>
            <origin xyz="0 0.043 0" rpy="${-pi/2} 0 0"/>
        </joint>
    </xacro:macro>
</robot>